<?xml version="1.0" ?>
<robot xmlns:xacro="https://www.ros.org/wiki/xacro">
	<xacro:macro name="joint_revolute" params="name axis e_limit l_limit u_limit v_limit origin_rpy origin_xyz parent child mechanicalReduction">
		<joint name="${name}" type="revolute">
			<axis xyz="${axis}"/>
			<limit effort="${e_limit}" lower="${l_limit}" upper="${u_limit}" velocity="${v_limit}"/>
			<origin rpy="${origin_rpy}" xyz="${origin_xyz}"/>
			<parent link="${parent}"/>
			<child link="${child}"/>
		</joint>
		<transmission name="trans_${name}">
			<type>transmission_interface/SimpleTransmission</type>
			<joint name="${name}">
				<hardwareInterface>hardware_interface/PositionJointInterface</hardwareInterface>
			</joint>
			<actuator name="motor_${name}">
				<mechanicalReduction>${mechanicalReduction}</mechanicalReduction>
				<hardwareInterface>hardware_interface/PositionJointInterface</hardwareInterface>
			</actuator>
		</transmission>
	</xacro:macro>
</robot>